<?xml version='1.0'?>
<sdf version='1.6'>
  <model name='pitcheron'>

    <pose>0 0 0 0 0 0</pose>

    <link name='base_link'>
      <inertial>
        <mass>47</mass>
        <pose frame=''>0 0 0 0 -0 0</pose>
        <inertia>
          <ixx>0.11644594</ixx>
          <ixy>0</ixy>
          <ixz>0</ixz>
          <iyy>36.28891523</iyy>
          <iyz>0</iyz>
          <izz>36.18768153</izz>
        </inertia>
      </inertial>
      <pose frame=''>0 0 1.490810 0 -0 0</pose>
      <gravity>1</gravity>
      <visual name='base_link_visual'>
        <pose frame=''>0.240000 0 0.020000 0 0 3.14159</pose>
        <geometry>
          <mesh>
            <scale>0.001 0.001 0.001</scale>
            <uri>model://pitcheron/mesh/AnalyseModel-Fuselage-003.dae</uri>
          </mesh>
        </geometry>
        <material>
          <script>
            <uri>file://media/materials/scripts/gazebo.material</uri>
            <name>Gazebo/Grey</name>
          </script>
        </material>
        <transparency>0</transparency>
        <cast_shadows>1</cast_shadows>
      </visual>
      <collision name='base_link_collision'>
        <laser_retro>0</laser_retro>
        <max_contacts>10</max_contacts>
        <pose frame=''>0 0 0 0 -0 0</pose>
        <geometry>
          <box>
            <size>3.03932 0.0440676 0.1667</size>
          </box>
        </geometry>
        <surface>
          <friction>
            <ode>
              <mu>1</mu>
              <mu2>1</mu2>
              <fdir1>0 0 0</fdir1>
              <slip1>0</slip1>
              <slip2>0</slip2>
            </ode>
            <torsional>
              <coefficient>1</coefficient>
              <patch_radius>0</patch_radius>
              <surface_radius>0</surface_radius>
              <use_patch_radius>1</use_patch_radius>
              <ode>
                <slip>0</slip>
              </ode>
            </torsional>
          </friction>
          <bounce>
            <restitution_coefficient>0</restitution_coefficient>
            <threshold>1e+06</threshold>
          </bounce>
          <contact>
            <collide_without_contact>0</collide_without_contact>
            <collide_without_contact_bitmask>1</collide_without_contact_bitmask>
            <collide_bitmask>1</collide_bitmask>
            <ode>
              <soft_cfm>0</soft_cfm>
              <soft_erp>0.2</soft_erp>
              <kp>1e+13</kp>
              <kd>1</kd>
              <max_vel>10</max_vel>
              <min_depth>0.01</min_depth>
            </ode>
            <bullet>
              <split_impulse>1</split_impulse>
              <split_impulse_penetration_threshold>-0.01</split_impulse_penetration_threshold>
              <soft_cfm>0</soft_cfm>
              <soft_erp>0.2</soft_erp>
              <kp>1e+13</kp>
              <kd>1</kd>
            </bullet>
          </contact>
        </surface>
      </collision>
      <velocity_decay/>
    </link>

    <!-- control surfaces links -->

    <link name='elevator_link'>
      <inertial>
        <mass>1e-08</mass>
        <inertia>
          <ixx>1e-06</ixx>
          <ixy>0</ixy>
          <iyy>1e-06</iyy>
          <ixz>0</ixz>
          <iyz>0</iyz>
          <izz>1e-06</izz>
        </inertia>
        <pose frame=''>0 0 0 0 -0 0</pose>
      </inertial>
      <pose frame=''>-1.486622 0 1.507310 0 -0 0</pose>
      <visual name='elevator_link_visual'>
        <pose frame=''>0 0 0 0 -0 0</pose>
        <geometry>
          <box>
            <size>0.107408 0.562568 0.044178</size>
          </box>
        </geometry>
        <material>
          <script>
            <uri>file://media/materials/scripts/gazebo.material</uri>
            <name>Gazebo/Grey</name>
          </script>
        </material>
        <transparency>1</transparency>
        <cast_shadows>1</cast_shadows>
      </visual>
    </link>
    <link name='left_wing_bottom_link'>
      <inertial>
        <mass>1e-08</mass>
        <inertia>
          <ixx>1e-06</ixx>
          <ixy>0</ixy>
          <iyy>1e-06</iyy>
          <ixz>0</ixz>
          <iyz>0</iyz>
          <izz>1e-06</izz>
        </inertia>
        <pose frame=''>0 0 0 0 -0 0</pose>
      </inertial>
      <pose frame=''>0.270000 0.110000 1.420000 0 0 0</pose>
      <visual name='left_wing_bottom_link_visual'>
        <pose frame=''>-0.030000 -0.110000 0.090000 0 -0 3.14159</pose>
        <geometry>
          <mesh>
            <scale>0.001 0.001 0.001</scale>
            <uri>model://pitcheron/mesh/AnalyseModel-Left-Bottom-Wing-003.dae</uri>
          </mesh>
        </geometry>
        <material>
          <script>
            <uri>file://media/materials/scripts/gazebo.material</uri>
            <name>Gazebo/Grey</name>
          </script>
        </material>
        <transparency>0</transparency>
        <cast_shadows>1</cast_shadows>
      </visual>
    </link>
    <link name='left_wing_top_link'>
      <inertial>
        <mass>1e-08</mass>
        <inertia>
          <ixx>1e-06</ixx>
          <ixy>0</ixy>
          <iyy>1e-06</iyy>
          <ixz>0</ixz>
          <iyz>0</iyz>
          <izz>1e-06</izz>
        </inertia>
        <pose frame=''>0 0 0 0 -0 0</pose>
      </inertial>
      <pose frame=''>0.270000 0.110000 1.600000 0 0 0</pose>
      <visual name='left_wing_top_link_visual'>
        <pose frame=''>-0.030000 -0.110000 -0.090000 0 -0 3.14159</pose>
        <geometry>
          <mesh>
            <scale>0.001 0.001 0.001</scale>
            <uri>model://pitcheron/mesh/AnalyseModel-Left-Top-Wing-003.dae</uri>
          </mesh>
        </geometry>
        <material>
          <script>
            <uri>file://media/materials/scripts/gazebo.material</uri>
            <name>Gazebo/Grey</name>
          </script>
        </material>
        <transparency>0</transparency>
        <cast_shadows>1</cast_shadows>
      </visual>
    </link>
    <link name='right_wing_bottom_link'>
      <inertial>
        <mass>1e-08</mass>
        <inertia>
          <ixx>1e-06</ixx>
          <ixy>0</ixy>
          <iyy>1e-06</iyy>
          <ixz>0</ixz>
          <iyz>0</iyz>
          <izz>1e-06</izz>
        </inertia>
        <pose frame=''>0 0 0 0 -0 0</pose>
      </inertial>
      <pose frame=''>0.270000 -0.110000 1.420000 0 0 0</pose>
      <visual name='right_wing_bottom_link_visual'>
        <pose frame=''>-0.030000 0.110000 0.090000 0 -0 3.14159</pose>
        <geometry>
          <mesh>
            <scale>0.001 0.001 0.001</scale>
            <uri>model://pitcheron/mesh/AnalyseModel-Right-Bottom-Wing-003.dae</uri>
          </mesh>
        </geometry>
        <material>
          <script>
            <uri>file://media/materials/scripts/gazebo.material</uri>
            <name>Gazebo/Grey</name>
          </script>
        </material>
        <transparency>0</transparency>
        <cast_shadows>1</cast_shadows>
      </visual>
    </link>
    <link name='right_wing_top_link'>
      <inertial>
        <mass>1e-08</mass>
        <inertia>
          <ixx>1e-06</ixx>
          <ixy>0</ixy>
          <iyy>1e-06</iyy>
          <ixz>0</ixz>
          <iyz>0</iyz>
          <izz>1e-06</izz>
        </inertia>
        <pose frame=''>0 0 0 0 -0 0</pose>
      </inertial>
      <pose frame=''>0.270000 -0.110000 1.600000 0 0 0</pose>
      <visual name='right_wing_top_link_visual'>
        <pose frame=''>-0.030000 0.110000 -0.090000 0 -0 3.14159</pose>
        <geometry>
          <mesh>
            <scale>0.001 0.001 0.001</scale>
            <uri>model://pitcheron/mesh/AnalyseModel-Right-Top-Wing-003.dae</uri>
          </mesh>
        </geometry>
        <material>
          <script>
            <uri>file://media/materials/scripts/gazebo.material</uri>
            <name>Gazebo/Grey</name>
          </script>
        </material>
        <transparency>0</transparency>
        <cast_shadows>1</cast_shadows>
      </visual>
    </link>
    <link name='rudder_link'>
      <inertial>
        <mass>1e-08</mass>
        <inertia>
          <ixx>1e-06</ixx>
          <ixy>0</ixy>
          <iyy>1e-06</iyy>
          <ixz>0</ixz>
          <iyz>0</iyz>
          <izz>1e-06</izz>
        </inertia>
        <pose frame=''>0 0 0 0 -0 0</pose>
      </inertial>
      <pose frame=''>-1.446240 0 1.682760 0 -0 0</pose>
      <visual name='rudder_link_visual'>
        <pose frame=''>0 0 0 0 -0 0</pose>
        <geometry>
          <box>
            <size>0.130490 0.060154 0.221761</size>
          </box>
        </geometry>
        <material>
          <script>
            <uri>file://media/materials/scripts/gazebo.material</uri>
            <name>Gazebo/Grey</name>
          </script>
          <emissive>0 0 0 1</emissive>
        </material>
        <transparency>1</transparency>
        <cast_shadows>1</cast_shadows>
      </visual>
    </link>

    <!-- control surfaces joints -->

    <joint name='elevator_joint' type='fixed'>
      <parent>base_link</parent>
      <child>elevator_link</child>
      <pose frame=''>0 0 0 0 -0.261799 0</pose>
      <physics>
        <ode>
          <limit>
            <cfm>0</cfm>
            <erp>0.2</erp>
          </limit>
          <suspension>
            <cfm>0</cfm>
            <erp>0.2</erp>
          </suspension>
        </ode>
      </physics>
    </joint>
    <joint name='left_wing_bottom_joint' type='revolute'>
      <parent>base_link</parent>
      <child>left_wing_bottom_link</child>
      <pose frame=''>0 0 0 0 -0 0</pose>
      <axis>
        <xyz>0 1 0</xyz>
        <limit>
          <!-- -15/+15 deg. -->
          <lower>-0.261799</lower>
          <upper>0.261799</upper>
        </limit>
        <dynamics>
          <damping>1.000</damping>
        </dynamics>
      </axis>
      <physics>
        <ode>
          <implicit_spring_damper>1</implicit_spring_damper>
        </ode>
      </physics>
    </joint>
    <joint name='left_wing_top_joint' type='revolute'>
      <parent>base_link</parent>
      <child>left_wing_top_link</child>
      <pose frame=''>0 0 0 0 -0 0</pose>
      <axis>
        <xyz>0 1 0</xyz>
        <limit>
          <!-- -15/+15 deg. -->
          <lower>-0.261799</lower>
          <upper>0.261799</upper>
        </limit>
        <dynamics>
          <damping>1.000</damping>
        </dynamics>
      </axis>
      <physics>
        <ode>
          <implicit_spring_damper>1</implicit_spring_damper>
        </ode>
      </physics>
    </joint>
    <joint name='right_wing_bottom_joint' type='revolute'>
      <parent>base_link</parent>
      <child>right_wing_bottom_link</child>
      <pose frame=''>0 0 0 0 -0 0</pose>
      <axis>
        <xyz>0 1 0</xyz>
        <limit>
          <!-- -15/+15 deg. -->
          <lower>-0.261799</lower>
          <upper>0.261799</upper>
        </limit>
        <dynamics>
          <damping>1.000</damping>
        </dynamics>
      </axis>
      <physics>
        <ode>
          <implicit_spring_damper>1</implicit_spring_damper>
        </ode>
      </physics>
    </joint>
    <joint name='right_wing_top_joint' type='revolute'>
      <parent>base_link</parent>
      <child>right_wing_top_link</child>
      <pose frame=''>0 0 0 0 -0 0</pose>
      <axis>
        <xyz>0 1 0</xyz>
        <limit>
          <!-- -15/+15 deg. -->
          <lower>-0.261799</lower>
          <upper>0.261799</upper>
        </limit>
        <dynamics>
          <damping>1.000</damping>
        </dynamics>
      </axis>
      <physics>
        <ode>
          <implicit_spring_damper>1</implicit_spring_damper>
        </ode>
      </physics>
    </joint>
    <joint name='rudder_joint' type='fixed'>
      <parent>base_link</parent>
      <child>rudder_link</child>
      <pose frame=''>0 0 0 0 -0 0</pose>
      <physics>
        <ode>
          <limit>
            <cfm>0</cfm>
            <erp>0.2</erp>
          </limit>
          <suspension>
            <cfm>0</cfm>
            <erp>0.2</erp>
          </suspension>
        </ode>
      </physics>
    </joint>

    <static>0</static>

    <allow_auto_disable>1</allow_auto_disable>

    <!-- control surfaces plugins -->

    <plugin name='left_wing_bottom_plugin' filename='libLiftDragPlugin.so'>
      <!-- 6 degrees angle of attack -->
      <a0>0.10472</a0> <!-- angle of attack in radians as a double precision point value -->
      <cla>4.705845611</cla> <!-- as a coeficient unitless as a double precision point value -->
      <cda>0.3817188071</cda> <!-- as a coeficient unitless as a double precision point value -->
      <cma>0.0</cma> <!-- Coefficient of Moment / alpha slope. unitless as a double precision point value NOTE: this is zero on the lane model--> 
      <!-- set to 10 degrees -->
      <alpha_stall>0.1745329252</alpha_stall> <!-- is the angle at which it starts stalling -->
      <cla_stall>-6.606203378</cla_stall> <!-- as a coeficient unitless as a double precision point value -->
      <cda_stall>1.28113363</cda_stall> <!-- as a coeficient unitless as a double precision point value -->
      <cma_stall>0</cma_stall> <!-- Coefficient of Moment / alpha slope. unitless as a double precision point value NOTE: this is zero on the lane model--> 
      <cp>0 0.280 0</cp> <!-- link coordinates of center of pressure int Vector 3 (x,y,x) relative to center of link -->
      <area>0.6</area> <!-- area of the link in m^2 as a double precision point value -->
      <air_density>0.81935</air_density>  <!-- air density in kg/m3 as a double precision point value --> 
      <forward>1 0 0</forward> <!-- Normally, this is taken as a direction parallel to the chord of the airfoil in zero angle of attack forward flight. (x,y,z)-->
      <upward>0 0 1</upward> <!--Inflow velocity orthogonal to forward and upward vectors is considered flow in the wing sweep direction. (x,y.z)-->
      <link_name>base_link</link_name>
      <control_joint_name>left_wing_bottom_joint</control_joint_name>
      <control_joint_rad_to_cl>-0.5</control_joint_rad_to_cl>
      <robotNamespace></robotNamespace>
      <windSubTopic>world_wind</windSubTopic>
    </plugin>
    <plugin name='left_wing_top_plugin' filename='libLiftDragPlugin.so'>
      <a0>0.10472</a0>
      <cla>4.705845611</cla>
      <cda>0.3817188071</cda>
      <cma>0.0</cma>
      <alpha_stall>0.1745329252</alpha_stall>
      <cla_stall>-6.606203378</cla_stall>
      <cda_stall>1.28113363</cda_stall>
      <cma_stall>0</cma_stall>
      <cp>0 0.280 0</cp>
      <area>0.6</area>
      <air_density>0.81935</air_density>
      <forward>1 0 0</forward>
      <upward>0 0 1</upward>
      <link_name>base_link</link_name>
      <control_joint_name>left_wing_top_joint</control_joint_name>
      <control_joint_rad_to_cl>-0.5</control_joint_rad_to_cl>
      <robotNamespace></robotNamespace>
      <windSubTopic>world_wind</windSubTopic>
    </plugin>
    <plugin name='right_wing_bottom_plugin' filename='libLiftDragPlugin.so'>
      <a0>0.10472</a0>
      <cla>4.705845611</cla>
      <cda>0.3817188071</cda>
      <cma>0.0</cma>
      <alpha_stall>0.1745329252</alpha_stall>
      <cla_stall>-6.606203378</cla_stall>
      <cda_stall>1.28113363</cda_stall>
      <cma_stall>0</cma_stall>
      <cp>0 -0.280 0</cp>
      <area>0.6</area>
      <air_density>0.81935</air_density>
      <forward>1 0 0</forward>
      <upward>0 0 1</upward>
      <link_name>base_link</link_name>
      <control_joint_name>right_wing_bottom_joint</control_joint_name>
      <control_joint_rad_to_cl>-0.5</control_joint_rad_to_cl>
      <robotNamespace></robotNamespace>
      <windSubTopic>world_wind</windSubTopic>
    </plugin>
    <plugin name='right_wing_top_plugin' filename='libLiftDragPlugin.so'>
      <a0>0.10472</a0>
      <cla>4.705845611</cla>
      <cda>0.3817188071</cda>
      <cma>0.0</cma>
      <alpha_stall>0.1745329252</alpha_stall>
      <cla_stall>-6.606203378</cla_stall>
      <cda_stall>1.28113363</cda_stall>
      <cma_stall>0</cma_stall>
      <cp>0 -0.280 0</cp>
      <area>0.6</area>
      <air_density>0.81935</air_density>
      <forward>1 0 0</forward>
      <upward>0 0 1</upward>
      <link_name>base_link</link_name>
      <control_joint_name>right_wing_top_joint</control_joint_name>
      <control_joint_rad_to_cl>-0.5</control_joint_rad_to_cl>
      <robotNamespace></robotNamespace>
      <windSubTopic>world_wind</windSubTopic>
    </plugin>
    <plugin name='rudder_pliugin' filename='libLiftDragPlugin.so'>
      <a0>0.0</a0>
      <cla>4.752798721</cla>
      <cda>0.6417112299</cda>
      <cma>0.0</cma>
      <alpha_stall>0.3391428111</alpha_stall>
      <cla_stall>-3.85</cla_stall>
      <cda_stall>-0.9233984055</cda_stall>
      <cma_stall>0</cma_stall>
      <cp>-0.5 0 0.05</cp>
      <area>0.2</area>
      <air_density>0.81935</air_density>
      <forward>1 0 0</forward>
      <upward>0 1 0</upward>
      <link_name>base_link</link_name>
      <control_joint_name>rudder_link</control_joint_name>
      <control_joint_rad_to_cl>4.0</control_joint_rad_to_cl>
      <robotNamespace/>
      <windSubTopic>world_wind</windSubTopic>
    </plugin>
    <plugin name='elevator_plugin' filename='libLiftDragPlugin.so'>
      <a0>-0.2</a0> 
      <cla>4.752798721</cla> 
      <cda>0.6417112299</cda> 
      <cma>0.0</cma> 
      <alpha_stall>0.3391428111</alpha_stall>
      <cla_stall>-3.85</cla_stall>
      <cda_stall>-0.9233984055</cda_stall>
      <cma_stall>0</cma_stall>
      <cp>-0.5 0 0</cp> 
      <area>0.01</area> 
      <air_density>1.2041</air_density> 
      <forward>1 0 0</forward> 
      <upward>0 0 1</upward> 
      <link_name>base_link</link_name>
      <control_joint_name>elevator_link</control_joint_name>
      <control_joint_rad_to_cl>-4.0</control_joint_rad_to_cl>
      <robotNamespace></robotNamespace>
      <windSubTopic>world_wind</windSubTopic>
    </plugin>

    <!-- sensor and interface links -->
    <link name='pitcheron/imu_link'>
      <pose>0 0 0 0 0 0</pose>
      <inertial>
        <pose>0 0 0 0 0 0</pose>
        <mass>0.015</mass>
        <inertia>
          <ixx>1e-05</ixx>
          <ixy>0</ixy>
          <ixz>0</ixz>
          <iyy>1e-05</iyy>
          <iyz>0</iyz>
          <izz>1e-05</izz>
        </inertia>
      </inertial>
    </link>
    <link name='pitcheron/airspeed_link'>
      <pose>0 0 0 0 0 0</pose>
      <inertial>
        <pose>0 0 0 0 0 0</pose>
        <mass>0.015</mass>
        <inertia>
          <ixx>1e-05</ixx>
          <ixy>0</ixy>
          <ixz>0</ixz>
          <iyy>1e-05</iyy>
          <iyz>0</iyz>
          <izz>1e-05</izz>
        </inertia>
      </inertial>
    </link>

    <!-- sensor and interface joints -->
    <joint name='pitcheron/imu_joint' type='revolute'>
      <parent>base_link</parent>
      <child>pitcheron/imu_link</child>
      <axis>
        <xyz>1 0 0</xyz>
        <limit>
          <lower>0</lower>
          <upper>0</upper>
          <effort>0</effort>
          <velocity>0</velocity>
        </limit>
        <dynamics>
          <spring_reference>0</spring_reference>
          <spring_stiffness>0</spring_stiffness>
        </dynamics>
        <use_parent_model_frame>1</use_parent_model_frame>
      </axis>
    </joint>
    <joint name='pitcheron/airspeed_joint' type='revolute'>
      <child>pitcheron/airspeed_link</child>
      <parent>base_link</parent>
      <axis>
        <xyz>1 0 0</xyz>
        <limit>
          <lower>0</lower>
          <upper>0</upper>
          <effort>0</effort>
          <velocity>0</velocity>
        </limit>
        <dynamics>
          <spring_reference>0</spring_reference>
          <spring_stiffness>0</spring_stiffness>
        </dynamics>
        <use_parent_model_frame>1</use_parent_model_frame>
      </axis>
    </joint>

    <include>
      <uri>model://gps</uri>
      <pose>0 0 0 0 0 0</pose>
      <name>gps</name>
    </include>
    <joint name='gps_joint' type='fixed'>
      <child>gps::link</child>
      <parent>base_link</parent>
    </joint>
    <!-- sensors and interface plugins-->
    <plugin name='gazebo_imu_plugin' filename='libgazebo_imu_plugin.so'>
      <robotNamespace></robotNamespace>
      <linkName>pitcheron/imu_link</linkName>
      <imuTopic>/imu</imuTopic>
      <gyroscopeNoiseDensity>0.0003394</gyroscopeNoiseDensity>
      <gyroscopeRandomWalk>3.8785e-05</gyroscopeRandomWalk>
      <gyroscopeBiasCorrelationTime>1000.0</gyroscopeBiasCorrelationTime>
      <gyroscopeTurnOnBiasSigma>0.0087</gyroscopeTurnOnBiasSigma>
      <accelerometerNoiseDensity>0.004</accelerometerNoiseDensity>
      <accelerometerRandomWalk>0.006</accelerometerRandomWalk>
      <accelerometerBiasCorrelationTime>300.0</accelerometerBiasCorrelationTime>
      <accelerometerTurnOnBiasSigma>0.196</accelerometerTurnOnBiasSigma>
    </plugin>
    <plugin name='airspeed_plugin' filename='libgazebo_airspeed_plugin.so'>
      <robotNamespace/>
      <linkName>pitcheron/airspeed_link</linkName>
    </plugin>
    <plugin name='groundtruth_plugin' filename='libgazebo_groundtruth_plugin.so'>
      <robotNamespace/>
    </plugin>
    <plugin name='magnetometer_plugin' filename='libgazebo_magnetometer_plugin.so'>
      <robotNamespace/>
      <pubRate>100</pubRate>
      <noiseDensity>0.0004</noiseDensity>
      <randomWalk>6.4e-06</randomWalk>
      <biasCorrelationTime>600</biasCorrelationTime>
      <magTopic>/mag</magTopic>
    </plugin>
    <plugin name='barometer_plugin' filename='libgazebo_barometer_plugin.so'>
      <robotNamespace/>
      <pubRate>50</pubRate>
      <baroTopic>/baro</baroTopic>
    </plugin>
    <plugin name='mavlink_interface' filename='libgazebo_mavlink_interface.so'>
      <robotNamespace></robotNamespace>
      <imuSubTopic>/imu</imuSubTopic>
      <magSubTopic>/mag</magSubTopic>
      <baroSubTopic>/baro</baroSubTopic>
      <mavlink_addr>INADDR_ANY</mavlink_addr>
      <mavlink_tcp_port>4560</mavlink_tcp_port>
      <mavlink_udp_port>14560</mavlink_udp_port>
      <serialEnabled>false</serialEnabled>
      <serialDevice>/dev/ttyACM0</serialDevice>
      <baudRate>921600</baudRate>
      <qgc_addr>INADDR_ANY</qgc_addr>
      <qgc_udp_port>14550</qgc_udp_port>
      <sdk_addr>INADDR_ANY</sdk_addr>
      <sdk_udp_port>14540</sdk_udp_port>
      <hil_mode>false</hil_mode>
      <hil_state_level>false</hil_state_level>
      <enable_lockstep>true</enable_lockstep>
      <use_tcp>true</use_tcp>
      <motorSpeedCommandPubTopic>/gazebo/command/motor_speed</motorSpeedCommandPubTopic>
      <control_channels>
        <channel name="left_wing_top">
          <input_index>5</input_index>
          <input_offset>0</input_offset>
          <input_scaling>1</input_scaling>
          <zero_position_disarmed>0</zero_position_disarmed>
          <zero_position_armed>0</zero_position_armed>
          <joint_control_type>position_kinematic</joint_control_type>
          <joint_name>left_wing_top_joint</joint_name>
        </channel>
        <channel name="right_wing_top">
          <input_index>6</input_index>
          <input_offset>0</input_offset>
          <input_scaling>1</input_scaling>
          <zero_position_disarmed>0</zero_position_disarmed>
          <zero_position_armed>0</zero_position_armed>
          <joint_control_type>position_kinematic</joint_control_type>
          <joint_name>right_wing_top_joint</joint_name>
        </channel>
        <channel name="left_wing_bottom">
          <input_index>5</input_index>
          <input_offset>0</input_offset>
          <input_scaling>-1</input_scaling>
          <zero_position_disarmed>0</zero_position_disarmed>
          <zero_position_armed>0</zero_position_armed>
          <joint_control_type>position_kinematic</joint_control_type>
          <joint_name>left_wing_bottom_joint</joint_name>
        </channel>
        <channel name="right_wing_bottom">
          <input_index>6</input_index>
          <input_offset>0</input_offset>
          <input_scaling>-1</input_scaling>
          <zero_position_disarmed>0</zero_position_disarmed>
          <zero_position_armed>0</zero_position_armed>
          <joint_control_type>position_kinematic</joint_control_type>
          <joint_name>right_wing_bottom_joint</joint_name>
        </channel>
      </control_channels>
    </plugin>

  </model>
</sdf>
